Workbook

Sheet 상품코드_1월
F1: P0000BLA | G1: 지사비즈4종
F2: P00000ZC | G2: 컵비즈왁스묶음(4종)
C3: 도매 | D3: 인증살롱 | E3: 마스터 | F3: P00000YZ | G3: 컵비즈세트 | H3: 할인+증정 | J3: 합계
D4: P00000VS | E4: P00000QE | F4: P00000VM | G4: 묶음할인15% | H4: P0000BET
D5: P00000VR | E5: P00000QD | F5: P00000YS | G5: 스타터키트 | H5: 비즈2종묶음+선샤인증정
A6: 하드왁스 | E6: P0000BLR | F6: P00000YU | G6: 바디스타터키트 | K6: 도매 | L6: 인증살롱/마스터 | N6: 할인 | O6: 세트할인 | P6: 할인+증정 | Q6: 세트묶음할인 | R6: 품목별합계 | S6: 원가
A7: 아이브로우 | B7: P00000HT | C7: 80 | E7: 24 | F7: 1 | J7: =C7+D7+E7+F7+G7+I7+H7 -> 105 | K7: 2102700 | L7: =D7*19200 -> 0 | M7: =E7*19200 -> 460800 | O7: =F7*21040 -> 21040 | R7: =SUM(K7:Q7) -> 2584540 | S7: =(C7+D7+E7+F7+I7+H7+G7)*8655 -> 908775
A8: 하이브리드 | B8: P00000BV | C8: 7 | J8: =C8+D8+E8+F8+G8+I8+H8 -> 7 | K8: =C8*26300 -> 184100 | L8: =D8*19200 -> 0 | M8: =E8*19200 -> 0 | O8: =F8*20000 -> 0 | R8: =SUM(K8:Q8) -> 184100 | S8: =(C8+D8+E8+F8+I8+H8+G8)*8926 -> 62482
A9: 화이트 | B9: P00000CB | C9: 5 | J9: =C9+D9+E9+F9+G9+I9+H9 -> 5 | K9: =C9*26300 -> 131500 | L9: =D9*19200 -> 0 | M9: =E9*19200 -> 0 | O9: =F9*20000 -> 0 | R9: =SUM(K9:Q9) -> 131500 | S9: =(C9+D9+E9+F9+I9+H9+G9)*8926 -> 44630
A10: 슈퍼베리 | B10: P00000BX | C10: 2 | J10: =C10+D10+E10+F10+G10+I10+H10 -> 2 | K10: =C10*26300 -> 52600 | L10: =D10*19200 -> 0 | M10: =E10*19200 -> 0 | O10: =F10*20000 -> 0 | R10: =SUM(K10:Q10) -> 52600 | S10: =(C10+D10+E10+F10+I10+H10+G10)*8926 -> 17852
A11: 루비500g | J11: =C11+D11+E11+F11+G11+I11+H11 -> 0 | K11: =C11*26300 -> 0 | L11: =D11*19200 -> 0 | M11: =E11*19200 -> 0 | O11: =F11*20000 -> 0 | R11: =SUM(K11:Q11) -> 0 | S11: =(C11+D11+E11+G11+F11+I11+H11)*7042 -> 0
A12: 맨니하이브리드 | B12: P00000XE | C12: 12 | J12: =C12+D12+E12+F12+G12+I12+H12 -> 12 | K12: =C12*26300 -> 315600 | O12: =F12*20000 -> 0 | R12: =SUM(K12:Q12) -> 315600 | S12: =(C12+D12+E12+F12+I12+H12+G12)*8926 -> 107112
A13: 비즈하이브리드800 | B13: P0000BIF / P0000BLD / P0000BMJ P0000BMI | J13: =C13+D13+E13+F13+G13+I13+H13 -> 0 | K13: =C13*35500 -> 0 | O13: =F13*27300 -> 0 | R13: =SUM(K13:Q13) -> 0 | S13: =(C13+D13+E13+F13+I13+H13+G13)*14876 -> 0
A14: 비즈라벤다800 | C14: 2 | J14: =C14+D14+E14+F14+G14+I14+H14 -> 2 | K14: =C14*35500 -> 71000 | M14: =E14*33600 -> 0 | P14: =H14*32000 -> 0 | R14: =SUM(K14:Q14) -> 71000 | S14: =(C14+D14+E14+F14+I14+H14+G14)*14065 -> 28130
A15: 비즈로제트800 | C15: 1 | J15: =C15+D15+E15+F15+G15+I15+H15 -> 1 | K15: =C15*35500 -> 35500 | M15: =E15*33600 -> 0 | P15: =H15*32000 -> 0 | R15: =SUM(K15:Q15) -> 35500 | S15: =(C15+D15+E15+F15+I15+H15+G15)*14876 -> 14876
A16: 비즈핑키니800 | C16: 3 | J16: =C16+D16+E16+F16+G16+I16+H16 -> 3 | K16: =C16*40000 -> 120000 | M16: =E16*35500 -> 0 | P16: =H16*32000 -> 0 | R16: =SUM(K16:Q16) -> 120000 | S16: =(C16+D16+E16+F16+I16+H16+G16)*15958 -> 47874
A17: 선샤인비즈 | C17: 30 | E17: 36 | J17: =C17+D17+E17+F17+G17+I17+H17 -> 66 | K17: =C17*30000 -> 900000 | M17: =E17*20000 -> 720000 | N17: =F17*20000 -> 0 | R17: =SUM(K17:Q17) -> 1620000 | S17: =(C17+D17+E17+F17+I17+H17+G17)*13262 -> 875292
A18: 비즈하이브리드5KG | C18: 4 | E18: 2 | J18: =C18+D18+E18+F18+G18+I18+H18 -> 6 | K18: =C18*190000 -> 760000 | M18: =E18*154000 -> 308000 | R18: =SUM(K18:Q18) -> 1068000 | S18: =(C18+D18+E18+F18+I18+H18+G18)*89709 -> 538254
A19: 비즈라벤다5KG | C19: 1 | E19: 1 | J19: =C19+D19+E19+F19+G19+I19+H19 -> 2 | K19: =C19*190000 -> 190000 | M19: =E19*154000 -> 154000 | R19: =SUM(K19:Q19) -> 344000 | S19: =(C19+D19+E19+F19+I19+H19+G19)*85201 -> 170402
A20: 비즈로제트5KG | C20: 4 | J20: =C20+D20+E20+F20+G20+I20+H20 -> 4 | K20: 750000 | M20: =E20*154000 -> 0 | R20: =SUM(K20:Q20) -> 750000 | S20: =(C20+D20+E20+F20+I20+H20+G20)*89709 -> 358836
A21: 비즈핑키니5kg | C21: 4 | E21: 2 | J21: =C21+D21+E21+F21+G21+I21+H21 -> 6 | K21: =C21*206000 -> 824000 | M21: =E21*171000 -> 342000 | R21: =SUM(K21:Q21) -> 1166000 | S21: =(C21+D21+E21+F21+I21+H21+G21)*96471 -> 578826
A22: 데저트500 | J22: =C22+D22+E22+F22+G22+I22+H22 -> 0 | K22: =C22*25000 -> 0 | R22: =SUM(K22:Q22) -> 0 | S22: =(C22+D22+E22+F22+I22+H22+G22)*6110 -> 0
A23: 핑키니500g | J23: =C23+D23+E23+F23+G23+I23+H23 -> 0 | K23: =C23*25000 -> 0 | R23: =SUM(K23:Q23) -> 0 | S23: =(C23+D23+E23+F23+I23+H23+G23)*7100 -> 0
A24: 500g총합계 | C24: =SUM(C7:C23) -> 155 | D24: =SUM(D7:D23) -> 0 | E24: =SUM(E7:E23) -> 65 | F24: =SUM(F7:F23) -> 1 | G24: =SUM(G7:G23) -> 0 | H24: =SUM(H7:H23) -> 0 | I24: =SUM(I7:I23) -> 0 | J24: =SUM(J7:J23) -> 221 | ... S24: =SUM(S7:S23) -> 3753341
A25: 컵비즈왁스(로제트) | B25: P00000ZB | C25: 2 | F25: 1 | J25: =SUM(C25:I25) -> 3 | K25: =C25*6200 -> 12400 | N25: =F25*5580 -> 5580 | O25: =G25*4340 -> 0 | R25: =SUM(K25:Q25) -> 17980 | S25: =(C25+D25+E25+F25+I25+G25+H25)*4151 -> 12453
A26: 컵비즈왁스(라벤다) | C26: 3 | F26: 2 | J26: =SUM(C26:I26) -> 5 | K26: =C26*6200 -> 18600 | N26: =F26*5580 -> 11160 | O26: =G26*4340 -> 0 | R26: =SUM(K26:Q26) -> 29760 | S26: =(C26+D26+E26+F26+I26+G26+H26)*4050 -> 20250
A27: 컵비즈왁스(하이브리드) | C27: 2 | J27: =SUM(C27:I27) -> 2 | K27: =C27*6200 -> 12400 | N27: =F27*5580 -> 0 | O27: =G27*4340 -> 0 | R27: =SUM(K27:Q27) -> 12400 | S27: =(C27+D27+E27+F27+I27+G27+H27)*4151 -> 8302
A28: 컵비즈왁스(핑키니) | C28: 4 | F28: 2 | G28: 2 | J28: =SUM(C28:I28) -> 8 | K28: =C28*6200 -> 24800 | N28: =F28*5580 -> 11160 | O28: =G28*4340 -> 8680 | R28: =SUM(K28:Q28) -> 44640 | S28: =(C28+D28+E28+F28+I28+G28+H28)*4301 -> 34408
A29: 핑키니하드 | B29: P00000UH | C29: 32 | D29: 15 | E29: 74 | F29: 723 | J29: =SUM(C29:I29) -> 844 | K29: =C29*40000 -> 1280000 | L29: =D29*31000 -> 465000 | M29: 2259600 | N29: 24539500 | P29: =H29*34000 -> 0 | R29: =SUM(K29:Q29) -> 28544100 | S29: =(C29+D29+E29+F29+I29+G29+H29)*17852 -> 15067088
A30: 루비1kg | B30: P00000TI | C30: 25 | E30: 111 | F30: 710 | J30: =SUM(C30:I30) -> 846 | K30: 943200 | L30: =D30*27800 -> 0 | M30: 3065000 | N30: 22738860 | P30: =H30*32130 -> 0 | R30: =SUM(K30:Q30) -> 26747060 | S30: =(C30+D30+E30+F30+I30+G30+H30)*15958 -> 13500468
A31: 데저트 | B31: P00000BY | C31: 22 | D31: 1 | E31: 81 | F31: 553 | J31: =SUM(C31:I31) -> 657 | K31: 829800 | L31: =D31*28000 -> 28000 | M31: =E31*27800 -> 2251800 | N31: 17706690 | P31: =H31*32130 -> 0 | R31: =SUM(K31:Q31) -> 20816290 | S31: =(C31+D31+E31+F31+I31+G31+H31)*15958 -> 10484406
A32: 라벤더 | B32: P00000BZ | C32: 8 | E32: 50 | F32: 143 | J32: =SUM(C32:I32) -> 201 | K32: =C32*37800 -> 302400 | L32: =D32*27800 -> 0 | M32: 1390000 | N32: 4560930 | P32: =H32*32130 -> 0 | R32: =SUM(K32:Q32) -> 6253330 | S32: =(C32+D32+E32+F32+I32+G32+H32)*15958 -> 3207558
A33: 로제트 | B33: P00000CH | C33: 11 | D33: 4 | E33: 46 | F33: 252 | G33: 4 | J33: =SUM(C33:I33) -> 317 | K33: =C33*37800 -> 415800 | L33: =D33*28000 -> 112000 | M33: =E33*27800 -> 1278800 | N33: 8092170 | O33: =G33*30240 -> 120960 | P33: =H33*32130 -> 0 | R33: =SUM(K33:Q33) -> 10019730 | S33: =(C33+D33+E33+F33+I33+G33+H33)*16680 -> 5287560
A34: 맨니피코 | B34: P00000CG | C34: 20 | E34: 78 | F34: 324 | J34: =SUM(C34:I34) -> 422 | K34: 754200 | L34: =D34*27800 -> 0 | M34: =E34*27800 -> 2168400 | N34: 10407060 | P34: =H34*32130 -> 0 | R34: =SUM(K34:Q34) -> 13329660 | S34: =(C34+D34+E34+F34+I34+G34+H34)*16680 -> 7038960
A35: 올리브 | B35: P00000CA | C35: 2 | E35: 3 | F35: 76 | J35: =SUM(C35:I35) -> 81 | K35: =C35*37800 -> 75600 | L35: =D35*27800 -> 0 | M35: =E35*27800 -> 83400 | N35: =F35*32130 -> 2441880 | P35: =H35*32130 -> 0 | R35: =SUM(K35:Q35) -> 2600880 | S35: =(C35+D35+E35+F35+I35+G35+H35)*16680 -> 1351080
A36: 바닐라 | B36: P00000BW | C36: 3 | E36: 15 | F36: 48 | J36: =SUM(C36:I36) -> 66 | K36: =C36*37800 -> 113400 | L36: =D36*27800 -> 0 | M36: =E36*27800 -> 417000 | N36: =F36*32130 -> 1542240 | P36: =H36*32130 -> 0 | R36: =SUM(K36:Q36) -> 2072640 | S36: =(C36+D36+E36+F36+I36+G36+H36)*16680 -> 1100880
A37: 소베리 | B37: P00000CI | C37: 10 | E37: 39 | F37: 122 | J37: =SUM(C37:I37) -> 171 | K37: =C37*37800 -> 378000 | L37: =D37*27800 -> 0 | M37: =E37*27800 -> 1084200 | N37: 3901500 | P37: =H37*32130 -> 0 | R37: =SUM(K37:Q37) -> 5363700 | S37: =(C37+D37+E37+F37+I37+G37+H37)*16680 -> 2852280
A38: 아쥴렌 | B38: P00000CE | E38: 4 | F38: 14 | J38: =SUM(C38:I38) -> 18 | K38: =C38*37800 -> 0 | L38: =D38*27800 -> 0 | M38: =E38*27800 -> 111200 | N38: =F38*32130 -> 449820 | P38: =H38*32130 -> 0 | R38: =SUM(K38:Q38) -> 561020 | S38: =(C38+D38+E38+F38+I38+G38+H38)*16680 -> 300240
A39: 액티브골드 | B39: P00000KH | J39: =SUM(C39:I39) -> 0 | K39: =C39*37800 -> 0 | L39: =D39*27800 -> 0 | M39: =E39*27800 -> 0 | N39: =F39*32130 -> 0 | P39: =H39*32130 -> 0 | R39: =SUM(K39:Q39) -> 0 | S39: =(C39+D39+E39+F39+I39+G39+H39)*15688 -> 0
A40: 알로에 | B40: P00000CD | C40: 2 | F40: 86 | J40: =SUM(C40:I40) -> 88 | K40: =C40*37800 -> 75600 | L40: =D40*27800 -> 0 | M40: =E40*27800 -> 0 | N40: 2761650 | P40: =H40*32130 -> 0 | R40: =SUM(K40:Q40) -> 2837250 | S40: =(C40+D40+E40+F40+I40+G40+H40)*15688 -> 1380544
...

Sheet 상품코드_2월
F1: P0000BLA | G1: 지사비즈4종
F2: P00000ZC | G2: 컵비즈왁스묶음(4종)
C3: 도매 | D3: 인증살롱 | E3: 마스터 | F3: P00000YZ | G3: 컵비즈세트 | H3: 할인+증정 | J3: 합계
D4: P00000VS | E4: P00000QE | F4: P00000VM | G4: 묶음할인15% | H4: P0000BET
D5: P00000VR | E5: P00000QD | F5: P00000YS | G5: 스타터키트 | H5: 비즈2종묶음+선샤인증정
A6: 하드왁스 | E6: P0000BLR | F6: P00000YU | G6: 바디스타터키트 | K6: 도매 | L6: 인증살롱/마스터 | N6: 할인 | O6: 세트할인 | P6: 할인+증정 | Q6: 세트묶음할인 | R6: 품목별합계 | S6: 원가
A7: 아이브로우 | B7: P00000HT | C7: 41 | E7: 72 | J7: =C7+D7+E7+F7+G7+I7+H7 -> 113 | K7: =C7*26300 -> 1078300 | L7: =D7*19200 -> 0 | M7: =E7*19200 -> 1382400 | O7: =F7*21040 -> 0 | R7: =SUM(K7:Q7) -> 2460700 | S7: =(C7+D7+E7+F7+I7+H7+G7)*8655 -> 978015
A8: 하이브리드 | B8: P00000BV | C8: 11 | J8: =C8+D8+E8+F8+G8+I8+H8 -> 11 | K8: =C8*26300 -> 289300 | L8: =D8*19200 -> 0 | M8: =E8*19200 -> 0 | O8: =F8*20000 -> 0 | R8: =SUM(K8:Q8) -> 289300 | S8: =(C8+D8+E8+F8+I8+H8+G8)*8926 -> 98186
A9: 화이트 | B9: P00000CB | J9: =C9+D9+E9+F9+G9+I9+H9 -> 0 | K9: =C9*26300 -> 0 | L9: =D9*19200 -> 0 | M9: =E9*19200 -> 0 | O9: =F9*20000 -> 0 | R9: =SUM(K9:Q9) -> 0 | S9: =(C9+D9+E9+F9+I9+H9+G9)*8926 -> 0
A10: 슈퍼베리 | B10: P00000BX | C10: 7 | J10: =C10+D10+E10+F10+G10+I10+H10 -> 7 | K10: =C10*26300 -> 184100 | L10: =D10*19200 -> 0 | M10: =E10*19200 -> 0 | O10: =F10*20000 -> 0 | R10: =SUM(K10:Q10) -> 184100 | S10: =(C10+D10+E10+F10+I10+H10+G10)*8926 -> 62482
A11: 루비500g | J11: =C11+D11+E11+F11+G11+I11+H11 -> 0 | K11: =C11*26300 -> 0 | L11: =D11*19200 -> 0 | M11: =E11*19200 -> 0 | O11: =F11*20000 -> 0 | R11: =SUM(K11:Q11) -> 0 | S11: =(C11+D11+E11+G11+F11+I11+H11)*7042 -> 0
A12: 맨니하이브리드 | B12: P00000XE | C12: 9 | J12: =C12+D12+E12+F12+G12+I12+H12 -> 9 | K12: =C12*26300 -> 236700 | O12: =F12*20000 -> 0 | R12: =SUM(K12:Q12) -> 236700 | S12: =(C12+D12+E12+F12+I12+H12+G12)*8926 -> 80334
A13: 비즈하이브리드800 | B13: P0000BIF / P0000BLD / P0000BMJ P0000BMI | J13: =C13+D13+E13+F13+G13+I13+H13 -> 0 | K13: =C13*35500 -> 0 | O13: =F13*27300 -> 0 | R13: =SUM(K13:Q13) -> 0 | S13: =(C13+D13+E13+F13+I13+H13+G13)*14876 -> 0
A14: 비즈라벤다800 | C14: 1 | E14: 1 | J14: =C14+D14+E14+F14+G14+I14+H14 -> 2 | K14: =C14*35500 -> 35500 | M14: =E14*33600 -> 33600 | P14: =H14*32000 -> 0 | R14: =SUM(K14:Q14) -> 69100 | S14: =(C14+D14+E14+F14+I14+H14+G14)*14065 -> 28130
A15: 비즈로제트800 | C15: 4 | E15: 1 | J15: =C15+D15+E15+F15+G15+I15+H15 -> 5 | K15: =C15*35500 -> 142000 | M15: =E15*33600 -> 33600 | P15: =H15*32000 -> 0 | R15: =SUM(K15:Q15) -> 175600 | S15: =(C15+D15+E15+F15+I15+H15+G15)*14876 -> 74380
A16: 비즈핑키니800 | C16: 4 | J16: =C16+D16+E16+F16+G16+I16+H16 -> 4 | K16: =C16*40000 -> 160000 | M16: =E16*35500 -> 0 | P16: =H16*32000 -> 0 | R16: =SUM(K16:Q16) -> 160000 | S16: =(C16+D16+E16+F16+I16+H16+G16)*15958 -> 63832
A17: 선샤인비즈 | C17: 27 | F17: 54 | J17: =C17+D17+E17+F17+G17+I17+H17 -> 81 | K17: =C17*30000 -> 810000 | M17: =E17*20000 -> 0 | N17: =F17*20000 -> 1080000 | R17: =SUM(K17:Q17) -> 1890000 | S17: =(C17+D17+E17+F17+I17+H17+G17)*13262 -> 1074222
A18: 비즈하이브리드5KG | E18: 3 | J18: =C18+D18+E18+F18+G18+I18+H18 -> 3 | K18: =C18*190000 -> 0 | M18: =E18*154000 -> 462000 | R18: =SUM(K18:Q18) -> 462000 | S18: =(C18+D18+E18+F18+I18+H18+G18)*89709 -> 269127
A19: 비즈라벤다5KG | C19: 3 | E19: 2 | J19: =C19+D19+E19+F19+G19+I19+H19 -> 5 | K19: =C19*190000 -> 570000 | M19: =E19*154000 -> 308000 | R19: =SUM(K19:Q19) -> 878000 | S19: =(C19+D19+E19+F19+I19+H19+G19)*85201 -> 426005
A20: 비즈로제트5KG | C20: 3 | E20: 1 | J20: =C20+D20+E20+F20+G20+I20+H20 -> 4 | K20: =C20*190000 -> 570000 | M20: =E20*154000 -> 154000 | R20: =SUM(K20:Q20) -> 724000 | S20: =(C20+D20+E20+F20+I20+H20+G20)*89709 -> 358836
A21: 비즈핑키니5kg | C21: 4 | E21: 5 | J21: =C21+D21+E21+F21+G21+I21+H21 -> 9 | K21: =C21*206000 -> 824000 | M21: =E21*171000 -> 855000 | R21: =SUM(K21:Q21) -> 1679000 | S21: =(C21+D21+E21+F21+I21+H21+G21)*96471 -> 868239
A22: 데저트500 | J22: =C22+D22+E22+F22+G22+I22+H22 -> 0 | K22: =C22*25000 -> 0 | R22: =SUM(K22:Q22) -> 0 | S22: =(C22+D22+E22+F22+I22+H22+G22)*6110 -> 0
A23: 핑키니500g | J23: =C23+D23+E23+F23+G23+I23+H23 -> 0 | K23: =C23*25000 -> 0 | R23: =SUM(K23:Q23) -> 0 | S23: =(C23+D23+E23+F23+I23+H23+G23)*7100 -> 0
A24: 500g총합계 | C24: =SUM(C7:C23) -> 114 | D24: =SUM(D7:D23) -> 0 | E24: =SUM(E7:E23) -> 85 | F24: =SUM(F7:F23) -> 54 | G24: =SUM(G7:G23) -> 0 | H24: =SUM(H7:H23) -> 0 | I24: =SUM(I7:I23) -> 0 | J24: =SUM(J7:J23) -> 253 | ... S24: =SUM(S7:S23) -> 4381788
A25: 컵비즈왁스(로제트) | B25: P00000ZB | C25: 3 | F25: 6 | G25: 1 | J25: =SUM(C25:I25) -> 10 | K25: =C25*6200 -> 18600 | N25: =F25*5580 -> 33480 | O25: =G25*4340 -> 4340 | R25: =SUM(K25:Q25) -> 56420 | S25: =(C25+D25+E25+F25+I25+G25+H25)*3923 -> 39230
A26: 컵비즈왁스(라벤다) | C26: 2 | F26: 6 | G26: 1 | J26: =SUM(C26:I26) -> 9 | K26: =C26*6200 -> 12400 | N26: =F26*5580 -> 33480 | O26: =G26*4340 -> 4340 | R26: =SUM(K26:Q26) -> 50220 | S26: =(C26+D26+E26+F26+I26+G26+H26)*3923 -> 35307
A27: 컵비즈왁스(하이브리드) | C27: 1 | F27: 4 | G27: 1 | J27: =SUM(C27:I27) -> 6 | K27: =C27*6200 -> 6200 | N27: =F27*5580 -> 22320 | O27: =G27*4340 -> 4340 | R27: =SUM(K27:Q27) -> 32860 | S27: =(C27+D27+E27+F27+I27+G27+H27)*3923 -> 23538
A28: 컵비즈왁스(핑키니) | F28: 6 | G28: 1 | J28: =SUM(C28:I28) -> 7 | K28: =C28*6200 -> 0 | N28: =F28*5580 -> 33480 | O28: =G28*4340 -> 4340 | R28: =SUM(K28:Q28) -> 37820 | S28: =(C28+D28+E28+F28+I28+G28+H28)*3923 -> 27461
A29: 핑키니하드 | B29: P00000UH | C29: 44 | E29: 137 | F29: 692 | J29: =SUM(C29:I29) -> 873 | K29: =C29*40000 -> 1760000 | L29: =D29*30800 -> 0 | M29: =E29*30800 -> 4219600 | N29: =F29*34000 -> 23528000 | P29: =H29*34000 -> 0 | R29: =SUM(K29:Q29) -> 29507600 | S29: =(C29+D29+E29+F29+I29+G29+H29)*17852 -> 15584796
A30: 루비1kg | B30: P00000TI | C30: 36 | E30: 170 | F30: 649 | J30: =SUM(C30:I30) -> 855 | K30: =C30*37800 -> 1360800 | L30: =D30*27800 -> 0 | M30: =E30*27800 -> 4726000 | N30: =F30*32130 -> 20852370 | P30: =H30*32130 -> 0 | R30: =SUM(K30:Q30) -> 26939170 | S30: =(C30+D30+E30+F30+I30+G30+H30)*15958 -> 13644090
A31: 데저트 | B31: P00000BY | C31: 26 | E31: 168 | F31: 468 | J31: =SUM(C31:I31) -> 662 | K31: =C31*37800 -> 982800 | L31: =D31*27800 -> 0 | M31: =E31*27800 -> 4670400 | N31: =F31*32130 -> 15036840 | P31: =H31*32130 -> 0 | R31: =SUM(K31:Q31) -> 20690040 | S31: =(C31+D31+E31+F31+I31+G31+H31)*15958 -> 10564196
A32: 라벤더 | B32: P00000BZ | C32: 19 | E32: 40 | F32: 178 | J32: =SUM(C32:I32) -> 237 | K32: =C32*37800 -> 718200 | L32: =D32*27800 -> 0 | M32: =E32*27800 -> 1112000 | N32: =F32*32130 -> 5719140 | P32: =H32*32130 -> 0 | R32: =SUM(K32:Q32) -> 7549340 | S32: =(C32+D32+E32+F32+I32+G32+H32)*15958 -> 3782046
A33: 로제트 | B33: P00000CH | C33: 10 | E33: 123 | F33: 278 | J33: =SUM(C33:I33) -> 411 | K33: =C33*37800 -> 378000 | L33: =D33*27800 -> 0 | M33: =E33*27800 -> 3419400 | N33: =F33*32130 -> 8932140 | O33: =G33*30240 -> 0 | P33: =H33*32130 -> 0 | R33: =SUM(K33:Q33) -> 12729540 | S33: =(C33+D33+E33+F33+I33+G33+H33)*16680 -> 6855480
A34: 맨니피코 | B34: P00000CG | C34: 23 | E34: 63 | F34: 416 | J34: =SUM(C34:I34) -> 502 | K34: =C34*37800 -> 869400 | L34: =D34*27800 -> 0 | M34: =E34*27800 -> 1751400 | N34: =F34*32130 -> 13366080 | P34: =H34*32130 -> 0 | R34: =SUM(K34:Q34) -> 15986880 | S34: =(C34+D34+E34+F34+I34+G34+H34)*16680 -> 8373360
A35: 올리브 | B35: P00000CA | C35: 6 | F35: 2 | J35: =SUM(C35:I35) -> 8 | K35: =C35*37800 -> 226800 | L35: =D35*27800 -> 0 | M35: =E35*27800 -> 0 | N35: =F35*32130 -> 64260 | P35: =H35*32130 -> 0 | R35: =SUM(K35:Q35) -> 291060 | S35: =(C35+D35+E35+F35+I35+G35+H35)*16680 -> 133440
A36: 바닐라 | B36: P00000BW | C36: 5 | E36: 21 | F36: 72 | J36: =SUM(C36:I36) -> 98 | K36: =C36*37800 -> 189000 | L36: =D36*27800 -> 0 | M36: =E36*27800 -> 583800 | N36: =F36*32130 -> 2313360 | P36: =H36*32130 -> 0 | R36: =SUM(K36:Q36) -> 3086160 | S36: =(C36+D36+E36+F36+I36+G36+H36)*16680 -> 1634640
A37: 소베리 | B37: P00000CI | C37: 6 | F37: 3 | J37: =SUM(C37:I37) -> 9 | K37: =C37*37800 -> 226800 | L37: =D37*27800 -> 0 | M37: =E37*27800 -> 0 | N37: =F37*32130 -> 96390 | P37: =H37*32130 -> 0 | R37: =SUM(K37:Q37) -> 323190 | S37: =(C37+D37+E37+F37+I37+G37+H37)*16680 -> 150120
A38: 아쥴렌 | B38: P00000CE | C38: 1 | E38: 8 | F38: 35 | J38: =SUM(C38:I38) -> 44 | K38: =C38*37800 -> 37800 | L38: =D38*27800 -> 0 | M38: =E38*27800 -> 222400 | N38: =F38*32130 -> 1124550 | P38: =H38*32130 -> 0 | R38: =SUM(K38:Q38) -> 1384750 | S38: =(C38+D38+E38+F38+I38+G38+H38)*16680 -> 733920
A39: 액티브골드 | B39: P00000KH | J39: =SUM(C39:I39) -> 0 | K39: =C39*37800 -> 0 | L39: =D39*27800 -> 0 | M39: =E39*27800 -> 0 | N39: =F39*32130 -> 0 | P39: =H39*32130 -> 0 | R39: =SUM(K39:Q39) -> 0 | S39: =(C39+D39+E39+F39+I39+G39+H39)*15688 -> 0
A40: 알로에 | B40: P00000CD | C40: 4 | E40: 12 | F40: 104 | J40: =SUM(C40:I40) -> 120 | K40: =C40*37800 -> 151200 | L40: =D40*27800 -> 0 | M40: =E40*27800 -> 333600 | N40: =F40*32130 -> 3341520 | P40: =H40*32130 -> 0 | R40: =SUM(K40:Q40) -> 3826320 | S40: =(C40+D40+E40+F40+I40+G40+H40)*15688 -> 1882560
...

Sheet 상품코드_3월 
F1: P0000BLA | G1: 지사비즈4종
F2: P00000ZC | G2: 컵비즈왁스묶음(4종)
C3: 도매 | D3: 인증살롱 | E3: 마스터 | F3: P00000YZ | G3: 컵비즈세트 | H3: 할인+증정 | J3: 합계
D4: P00000VS | E4: P00000QE | F4: P00000VM | G4: 묶음할인15% | H4: P0000BET | I4: 아나프리증정
D5: P00000VR | E5: P00000QD | F5: P00000YS | G5: 스타터키트 | H5: P0000BMX | I5: 비즈5KG행사
A6: 하드왁스 | E6: P0000BLR | F6: P00000YU | G6: 바디스타터키트 | K6: 도매 | L6: 인증살롱/마스터 | N6: 할인 | O6: 세트할인 | P6: 할인+증정 | Q6: 세트묶음할인 | R6: 품목별합계 | S6: 원가
A7: 아이브로우 | B7: P00000HT | C7: 115 | F7: 4 | J7: =C7+D7+E7+F7+G7+I7+H7 -> 119 | K7: =C7*26300 -> 3024500 | L7: =D7*19200 -> 0 | M7: =E7*19200 -> 0 | O7: =F7*21040 -> 84160 | R7: =SUM(K7:Q7) -> 3108660 | S7: =(C7+D7+E7+F7+I7+H7+G7)*8655 -> 1029945
A8: 하이브리드 | B8: P00000BV | C8: 8 | J8: =C8+D8+E8+F8+G8+I8+H8 -> 8 | K8: =C8*26300 -> 210400 | L8: =D8*19200 -> 0 | M8: =E8*19200 -> 0 | O8: =F8*20000 -> 0 | R8: =SUM(K8:Q8) -> 210400 | S8: =(C8+D8+E8+F8+I8+H8+G8)*8926 -> 71408
A9: 화이트 | B9: P00000CB | C9: 7 | J9: =C9+D9+E9+F9+G9+I9+H9 -> 7 | K9: =C9*26300 -> 184100 | L9: =D9*19200 -> 0 | M9: =E9*19200 -> 0 | O9: =F9*20000 -> 0 | R9: =SUM(K9:Q9) -> 184100 | S9: =(C9+D9+E9+F9+I9+H9+G9)*8926 -> 62482
A10: 슈퍼베리 | B10: P00000BX | C10: 8 | J10: =C10+D10+E10+F10+G10+I10+H10 -> 8 | K10: =C10*26300 -> 210400 | L10: =D10*19200 -> 0 | M10: =E10*19200 -> 0 | O10: =F10*20000 -> 0 | R10: =SUM(K10:Q10) -> 210400 | S10: =(C10+D10+E10+F10+I10+H10+G10)*8926 -> 71408
A11: 루비500g | J11: =C11+D11+E11+F11+G11+I11+H11 -> 0 | K11: =C11*26300 -> 0 | L11: =D11*19200 -> 0 | M11: =E11*19200 -> 0 | O11: =F11*20000 -> 0 | R11: =SUM(K11:Q11) -> 0 | S11: =(C11+D11+E11+G11+F11+I11+H11)*7042 -> 0
A12: 맨니하이브리드 | B12: P00000XE | C12: 8 | J12: =C12+D12+E12+F12+G12+I12+H12 -> 8 | K12: =C12*26300 -> 210400 | O12: =F12*20000 -> 0 | R12: =SUM(K12:Q12) -> 210400 | S12: =(C12+D12+E12+F12+I12+H12+G12)*8926 -> 71408
A13: 비즈하이브리드800 | B13: P0000BIF / P0000BLD / P0000BMJ P0000BMI / P0000BMY (3월행사) | H13: 2 | J13: =C13+D13+E13+F13+G13+I13+H13 -> 2 | K13: =C13*35500 -> 0 | O13: =F13*27300 -> 0 | P13: =H13*26700 -> 53400 | R13: =SUM(K13:Q13) -> 53400 | S13: =(C13+D13+E13+F13+I13+H13+G13)*14876 -> 29752
A14: 비즈라벤다800 | C14: 3 | H14: 11 | J14: =C14+D14+E14+F14+G14+I14+H14 -> 14 | K14: =C14*35500 -> 106500 | M14: =E14*33600 -> 0 | P14: =H14*26700 -> 293700 | R14: =SUM(K14:Q14) -> 400200 | S14: =(C14+D14+E14+F14+I14+H14+G14)*14065 -> 196910
A15: 비즈로제트800 | C15: 5 | H15: 18 | J15: =C15+D15+E15+F15+G15+I15+H15 -> 23 | K15: =C15*35500 -> 177500 | M15: =E15*33600 -> 0 | P15: =H15*26700 -> 480600 | R15: =SUM(K15:Q15) -> 658100 | S15: =(C15+D15+E15+F15+I15+H15+G15)*14876 -> 342148
A16: 비즈핑키니800 | C16: 15 | H16: 47 | J16: =C16+D16+E16+F16+G16+I16+H16 -> 62 | K16: =C16*40000 -> 600000 | M16: =E16*35500 -> 0 | P16: =H16*30000 -> 1410000 | R16: =SUM(K16:Q16) -> 2010000 | S16: =(C16+D16+E16+F16+I16+H16+G16)*15958 -> 989396
A17: 선샤인비즈 | C17: 29 | H17: 337 | J17: =C17+D17+E17+F17+G17+I17+H17 -> 366 | K17: =C17*30000 -> 870000 | M17: =E17*20000 -> 0 | P17: =H17*19800 -> 6672600 | R17: =SUM(K17:Q17) -> 7542600 | S17: =(C17+D17+E17+F17+I17+H17+G17)*13262 -> 4853892
A18: 비즈하이브리드5KG | C18: 3 | E18: 5 | H18: 16 | J18: =C18+D18+E18+F18+G18+I18+H18 -> 24 | K18: =C18*190000 -> 570000 | M18: =E18*154000 -> 770000 | P18: =H18*142500 -> 2280000 | R18: =SUM(K18:Q18) -> 3620000 | S18: =(C18+D18+E18+F18+I18+H18+G18)*89709 -> 2153016
A19: 비즈라벤다5KG | C19: 1 | E19: 1 | H19: 31 | J19: =C19+D19+E19+F19+G19+I19+H19 -> 33 | K19: =C19*190000 -> 190000 | M19: =E19*154000 -> 154000 | P19: =H19*142500 -> 4417500 | R19: =SUM(K19:Q19) -> 4761500 | S19: =(C19+D19+E19+F19+I19+H19+G19)*85201 -> 2811633
A20: 비즈로제트5KG | C20: 1 | H20: 15 | J20: =C20+D20+E20+F20+G20+I20+H20 -> 16 | K20: =C20*190000 -> 190000 | M20: =E20*154000 -> 0 | P20: =H20*142500 -> 2137500 | R20: =SUM(K20:Q20) -> 2327500 | S20: =(C20+D20+E20+F20+I20+H20+G20)*89709 -> 1435344
A21: 비즈핑키니5kg | C21: 8 | H21: 98 | J21: =C21+D21+E21+F21+G21+I21+H21 -> 106 | K21: =C21*206000 -> 1648000 | M21: =E21*171000 -> 0 | P21: =H21*154500 -> 15141000 | R21: =SUM(K21:Q21) -> 16789000 | S21: =(C21+D21+E21+F21+I21+H21+G21)*96471 -> 10225926
A22: 데저트500 | J22: =C22+D22+E22+F22+G22+I22+H22 -> 0 | K22: =C22*25000 -> 0 | R22: =SUM(K22:Q22) -> 0 | S22: =(C22+D22+E22+F22+I22+H22+G22)*6110 -> 0
A23: 핑키니500g | J23: =C23+D23+E23+F23+G23+I23+H23 -> 0 | K23: =C23*25000 -> 0 | R23: =SUM(K23:Q23) -> 0 | S23: =(C23+D23+E23+F23+I23+H23+G23)*7100 -> 0
A24: 500g총합계 | C24: =SUM(C7:C23) -> 211 | D24: =SUM(D7:D23) -> 0 | E24: =SUM(E7:E23) -> 6 | F24: =SUM(F7:F23) -> 4 | G24: =SUM(G7:G23) -> 0 | H24: =SUM(H7:H23) -> 575 | I24: =SUM(I7:I23) -> 0 | J24: =SUM(J7:J23) -> 796 | ... S24: =SUM(S7:S23) -> 24344668
A25: 컵비즈왁스(로제트) | B25: P00000ZB | C25: 2 | F25: 1 | J25: =SUM(C25:I25) -> 3 | K25: =C25*6200 -> 12400 | N25: =F25*5580 -> 5580 | O25: =G25*4340 -> 0 | R25: =SUM(K25:Q25) -> 17980 | S25: =(C25+D25+E25+F25+I25+G25+H25)*3923 -> 11769
A26: 컵비즈왁스(라벤다) | C26: 4 | F26: 8 | G26: 1 | J26: =SUM(C26:I26) -> 13 | K26: =C26*6200 -> 24800 | N26: =F26*5580 -> 44640 | O26: =G26*4340 -> 4340 | R26: =SUM(K26:Q26) -> 73780 | S26: =(C26+D26+E26+F26+I26+G26+H26)*3923 -> 50999
A27: 컵비즈왁스(하이브리드) | C27: 2 | F27: 3 | J27: =SUM(C27:I27) -> 5 | K27: =C27*6200 -> 12400 | N27: =F27*5580 -> 16740 | O27: =G27*4340 -> 0 | R27: =SUM(K27:Q27) -> 29140 | S27: =(C27+D27+E27+F27+I27+G27+H27)*3923 -> 19615
A28: 컵비즈왁스(핑키니) | C28: 7 | F28: 3 | G28: 1 | J28: =SUM(C28:I28) -> 11 | K28: =C28*6200 -> 43400 | N28: =F28*5580 -> 16740 | O28: =G28*4340 -> 4340 | R28: =SUM(K28:Q28) -> 64480 | S28: =(C28+D28+E28+F28+I28+G28+H28)*3923 -> 43153
A29: 핑키니하드 | B29: P00000UH | C29: 40 | E29: 149 | F29: 317 | H29: 148 | J29: =SUM(C29:I29) -> 654 | K29: =C29*40000 -> 1600000 | L29: =D29*30800 -> 0 | M29: =E29*30800 -> 4589200 | N29: =F29*34000 -> 10778000 | P29: =H29*34000 -> 5032000 | R29: =SUM(K29:Q29) -> 21999200 | S29: =(C29+D29+E29+F29+I29+G29+H29)*17852 -> 11675208
A30: 루비1kg | B30: P00000TI | C30: 14 | E30: 56 | F30: 336 | H30: 15 | J30: =SUM(C30:I30) -> 421 | K30: =C30*37800 -> 529200 | L30: =D30*27800 -> 0 | M30: =E30*27800 -> 1556800 | N30: =F30*32130 -> 10795680 | P30: =H30*32130 -> 481950 | R30: =SUM(K30:Q30) -> 13363630 | S30: =(C30+D30+E30+F30+I30+G30+H30)*15958 -> 6718318
A31: 데저트 | B31: P00000BY | C31: 56 | E31: 214 | F31: 459 | H31: 396 | J31: =SUM(C31:I31) -> 1125 | K31: =C31*37800 -> 2116800 | L31: =D31*27800 -> 0 | M31: =E31*27800 -> 5949200 | N31: =F31*32130 -> 14747670 | P31: =H31*32130 -> 12723480 | R31: =SUM(K31:Q31) -> 35537150 | S31: =(C31+D31+E31+F31+I31+G31+H31)*15958 -> 17952750
A32: 라벤더 | B32: P00000BZ | C32: 34 | E32: 84 | F32: 152 | H32: 90 | J32: =SUM(C32:I32) -> 360 | K32: =C32*37800 -> 1285200 | L32: =D32*27800 -> 0 | M32: =E32*27800 -> 2335200 | N32: =F32*32130 -> 4883760 | P32: =H32*32130 -> 2891700 | R32: =SUM(K32:Q32) -> 11395860 | S32: =(C32+D32+E32+F32+I32+G32+H32)*15958 -> 5744880
A33: 로제트 | B33: P00000CH | C33: 36 | E33: 157 | F33: 312 | G33: 1 | H33: 160 | J33: =SUM(C33:I33) -> 666 | K33: =C33*37800 -> 1360800 | L33: =D33*27800 -> 0 | M33: =E33*27800 -> 4364600 | N33: =F33*32130 -> 10024560 | O33: =G33*30240 -> 30240 | P33: =H33*32130 -> 5140800 | R33: =SUM(K33:Q33) -> 20921000 | S33: =(C33+D33+E33+F33+I33+G33+H33)*16680 -> 11108880
A34: 맨니피코 | B34: P00000CG | C34: 35 | E34: 89 | F34: 322 | H34: 243 | J34: =SUM(C34:I34) -> 689 | K34: =C34*37800 -> 1323000 | L34: =D34*27800 -> 0 | M34: =E34*27800 -> 2474200 | N34: =F34*32130 -> 10345860 | P34: =H34*32130 -> 7807590 | R34: =SUM(K34:Q34) -> 21950650 | S34: =(C34+D34+E34+F34+I34+G34+H34)*16680 -> 11492520
A35: 올리브 | B35: P00000CA | J35: =SUM(C35:I35) -> 0 | K35: =C35*37800 -> 0 | L35: =D35*27800 -> 0 | M35: =E35*27800 -> 0 | N35: =F35*32130 -> 0 | P35: =H35*32130 -> 0 | R35: =SUM(K35:Q35) -> 0 | S35: =(C35+D35+E35+F35+I35+G35+H35)*16680 -> 0
A36: 바닐라 | B36: P00000BW | C36: 15 | E36: 12 | F36: 36 | H36: 40 | J36: =SUM(C36:I36) -> 103 | K36: =C36*37800 -> 567000 | L36: =D36*27800 -> 0 | M36: =E36*27800 -> 333600 | N36: =F36*32130 -> 1156680 | P36: =H36*32130 -> 1285200 | R36: =SUM(K36:Q36) -> 3342480 | S36: =(C36+D36+E36+F36+I36+G36+H36)*16680 -> 1718040
A37: 소베리 | B37: P00000CI | C37: 4 | F37: 1 | J37: =SUM(C37:I37) -> 5 | K37: =C37*37800 -> 151200 | L37: =D37*27800 -> 0 | M37: =E37*27800 -> 0 | N37: =F37*32130 -> 32130 | P37: =H37*32130 -> 0 | R37: =SUM(K37:Q37) -> 183330 | S37: =(C37+D37+E37+F37+I37+G37+H37)*16680 -> 83400
A38: 아쥴렌 | B38: P00000CE | C38: 4 | E38: 20 | F38: 46 | H38: 33 | J38: =SUM(C38:I38) -> 103 | K38: =C38*37800 -> 151200 | L38: =D38*27800 -> 0 | M38: =E38*27800 -> 556000 | N38: =F38*32130 -> 1477980 | P38: =H38*32130 -> 1060290 | R38: =SUM(K38:Q38) -> 3245470 | S38: =(C38+D38+E38+F38+I38+G38+H38)*16680 -> 1718040
A39: 액티브골드 | B39: P00000KH | J39: =SUM(C39:I39) -> 0 | K39: =C39*37800 -> 0 | L39: =D39*27800 -> 0 | M39: =E39*27800 -> 0 | N39: =F39*32130 -> 0 | P39: =H39*32130 -> 0 | R39: =SUM(K39:Q39) -> 0 | S39: =(C39+D39+E39+F39+I39+G39+H39)*15688 -> 0
A40: 알로에 | B40: P00000CD | C40: 7 | E40: 14 | F40: 102 | H40: 85 | J40: =SUM(C40:I40) -> 208 | K40: =C40*37800 -> 264600 | L40: =D40*27800 -> 0 | M40: =E40*27800 -> 389200 | N40: =F40*32130 -> 3277260 | P40: =H40*32130 -> 2731050 | R40: =SUM(K40:Q40) -> 6662110 | S40: =(C40+D40+E40+F40+I40+G40+H40)*15688 -> 3263104
...

Sheet 상품코드_4월 
F1: P0000BLA | G1: 지사비즈4종
F2: P007000ZC | G2: 컵비즈왁스묶음(4종)
C3: 도매 | E3: 인증/마스터 | F3: P00000YZ | G3: 컵비즈세트 | H3: 할인+증정 | J3: 합계
E4: P00000QE | F4: P00000VM | G4: 묶음할인15%
E5: P00000QD | F5: P00000YS | G5: 스타터키트
A6: 하드왁스 | E6: P0000BLR | F6: P00000YU | G6: 바디스타터키트 | K6: 도매 | L6: 인증살롱/마스터 | N6: 할인 | O6: 스타터세트할인 | P6: 할인+증정 | Q6: 컵비즈세트할인 | R6: 품목별합계 | S6: 원가
A7: 라이코젯아이브로우500 | B7: P00000HT | C7: 75 | F7: 2 | J7: =C7+D7+E7+F7+G7+I7+H7 -> 77 | K7: =C7*26300 -> 1972500 | L7: =D7*19200 -> 0 | M7: =E7*19200 -> 0 | O7: =F7*21040 -> 42080 | R7: =SUM(K7:Q7) -> 2014580 | S7: =(C7+D7+E7+F7+I7+H7+G7)*8655 -> 666435
A8: 라이코드림하이브리드500 | B8: P00000BV | C8: 5 | J8: =C8+D8+E8+F8+G8+I8+H8 -> 5 | K8: =C8*26300 -> 131500 | L8: =D8*19200 -> 0 | M8: =E8*19200 -> 0 | O8: =F8*20000 -> 0 | R8: =SUM(K8:Q8) -> 131500 | S8: =(C8+D8+E8+F8+I8+H8+G8)*8926 -> 44630
A9: 라이코넥화이트500 | B9: P00000CB | C9: 5 | J9: =C9+D9+E9+F9+G9+I9+H9 -> 5 | K9: =C9*26300 -> 131500 | L9: =D9*19200 -> 0 | M9: =E9*19200 -> 0 | O9: =F9*20000 -> 0 | R9: =SUM(K9:Q9) -> 131500 | S9: =(C9+D9+E9+F9+I9+H9+G9)*8926 -> 44630
A10: 라이코텍슈퍼베리500 | B10: P00000BX | E10: 24 | J10: =C10+D10+E10+F10+G10+I10+H10 -> 24 | K10: =C10*26300 -> 0 | L10: =D10*19200 -> 0 | M10: =E10*19200 -> 460800 | O10: =F10*20000 -> 0 | R10: =SUM(K10:Q10) -> 460800 | S10: =(C10+D10+E10+F10+I10+H10+G10)*8926 -> 214224
A11: 루비500g | J11: =C11+D11+E11+F11+G11+I11+H11 -> 0 | K11: =C11*26300 -> 0 | L11: =D11*19200 -> 0 | M11: =E11*19200 -> 0 | O11: =F11*20000 -> 0 | R11: =SUM(K11:Q11) -> 0 | S11: =(C11+D11+E11+G11+F11+I11+H11)*7042 -> 0
A12: 맨니피코하이브리드500 | B12: P00000XE | C12: 6 | J12: =C12+D12+E12+F12+G12+I12+H12 -> 6 | K12: =C12*26300 -> 157800 | O12: =F12*20000 -> 0 | R12: =SUM(K12:Q12) -> 157800 | S12: =(C12+D12+E12+F12+I12+H12+G12)*8926 -> 53556
A13: 라이코드림하이브리드비즈800 | B13: P0000BIF / P0000BLD / P0000BMJ P0000BMI / | J13: =C13+D13+E13+F13+G13+I13+H13 -> 0 | K13: =C13*35500 -> 0 | O13: =F13*27300 -> 0 | P13: =H13*26700 -> 0 | R13: =SUM(K13:Q13) -> 0 | S13: =(C13+D13+E13+F13+I13+H13+G13)*14876 -> 0
A14: 라이코젯라벤다비즈800 | C14: 1 | J14: =C14+D14+E14+F14+G14+I14+H14 -> 1 | K14: =C14*35500 -> 35500 | M14: =E14*33600 -> 0 | P14: =H14*26700 -> 0 | R14: =SUM(K14:Q14) -> 35500 | S14: =(C14+D14+E14+F14+I14+H14+G14)*14065 -> 14065
A15: 로제트비즈800 | C15: 3 | J15: =C15+D15+E15+F15+G15+I15+H15 -> 3 | K15: =C15*35500 -> 106500 | M15: =E15*33600 -> 0 | P15: =H15*26700 -> 0 | R15: =SUM(K15:Q15) -> 106500 | S15: =(C15+D15+E15+F15+I15+H15+G15)*14876 -> 44628
A16: 핑키니하이브리드비즈800 | C16: 8 | J16: =C16+D16+E16+F16+G16+I16+H16 -> 8 | K16: =C16*40000 -> 320000 | M16: =E16*35500 -> 0 | P16: =H16*30000 -> 0 | R16: =SUM(K16:Q16) -> 320000 | S16: =(C16+D16+E16+F16+I16+H16+G16)*15958 -> 127664
A17: 선샤인비즈왁스800 | C17: 30 | E17: 18 | J17: =C17+D17+E17+F17+G17+I17+H17 -> 48 | K17: =C17*30000 -> 900000 | M17: =E17*20000 -> 360000 | P17: =H17*19800 -> 0 | R17: =SUM(K17:Q17) -> 1260000 | S17: =(C17+D17+E17+F17+I17+H17+G17)*13262 -> 636576
A18: 라이코드림하이브리드비즈5kg | C18: 2 | E18: 1 | J18: =C18+D18+E18+F18+G18+I18+H18 -> 3 | K18: =C18*190000 -> 380000 | M18: =E18*154000 -> 154000 | P18: =H18*142500 -> 0 | R18: =SUM(K18:Q18) -> 534000 | S18: =(C18+D18+E18+F18+I18+H18+G18)*89709 -> 269127
A19: 라이코젯라벤다비즈5kg | C19: 1 | E19: 2 | J19: =C19+D19+E19+F19+G19+I19+H19 -> 3 | K19: =C19*190000 -> 190000 | M19: =E19*154000 -> 308000 | P19: =H19*142500 -> 0 | R19: =SUM(K19:Q19) -> 498000 | S19: =(C19+D19+E19+F19+I19+H19+G19)*85201 -> 255603
A20: 로제트비즈5kg | C20: 2 | J20: =C20+D20+E20+F20+G20+I20+H20 -> 2 | K20: =C20*190000 -> 380000 | M20: =E20*154000 -> 0 | P20: =H20*142500 -> 0 | R20: =SUM(K20:Q20) -> 380000 | S20: =(C20+D20+E20+F20+I20+H20+G20)*89709 -> 179418
A21: 핑키니하이브리드비즈5kg | C21: 9 | E21: 3 | J21: =C21+D21+E21+F21+G21+I21+H21 -> 12 | K21: =C21*206000 -> 1854000 | M21: =E21*171000 -> 513000 | P21: =H21*154500 -> 0 | R21: =SUM(K21:Q21) -> 2367000 | S21: =(C21+D21+E21+F21+I21+H21+G21)*96471 -> 1157652
A22: 데저트500 | J22: =C22+D22+E22+F22+G22+I22+H22 -> 0 | K22: =C22*25000 -> 0 | R22: =SUM(K22:Q22) -> 0 | S22: =(C22+D22+E22+F22+I22+H22+G22)*6110 -> 0
A23: 핑키니500g | J23: =C23+D23+E23+F23+G23+I23+H23 -> 0 | K23: =C23*25000 -> 0 | R23: =SUM(K23:Q23) -> 0 | S23: =(C23+D23+E23+F23+I23+H23+G23)*7100 -> 0
A24: 500g총합계 | C24: =SUM(C7:C23) -> 147 | D24: =SUM(D7:D23) -> 0 | E24: =SUM(E7:E23) -> 48 | F24: =SUM(F7:F23) -> 2 | G24: =SUM(G7:G23) -> 0 | H24: =SUM(H7:H23) -> 0 | I24: =SUM(I7:I23) -> 0 | J24: =SUM(J7:J23) -> 197 | ... S24: =SUM(S7:S23) -> 3708208
A25: 라이콘컵왁스비즈(로제트) | B25: P00000ZB | C25: 2 | G25: 1 | J25: =SUM(C25:I25) -> 3 | K25: =C25*6200 -> 12400 | N25: =F25*5580 -> 0 | O25: =G25*4340 -> 4340 | R25: =SUM(K25:Q25) -> 16740 | S25: =(C25+D25+E25+F25+I25+G25+H25)*3923 -> 11769
A26: 라이콘컵왁스비즈(라벤다) | C26: 6 | G26: 1 | J26: =SUM(C26:I26) -> 7 | K26: =C26*6200 -> 37200 | N26: =F26*5580 -> 0 | O26: =G26*4340 -> 4340 | R26: =SUM(K26:Q26) -> 41540 | S26: =(C26+D26+E26+F26+I26+G26+H26)*3923 -> 27461
A27: 라이콘컵왁스비즈(하이브리드) | C27: 1 | F27: 5 | J27: =SUM(C27:I27) -> 6 | K27: =C27*6200 -> 6200 | N27: =F27*5580 -> 27900 | O27: =G27*4340 -> 0 | R27: =SUM(K27:Q27) -> 34100 | S27: =(C27+D27+E27+F27+I27+G27+H27)*3923 -> 23538
A28: 라이콘컵왁스비즈(핑키니) | C28: 6 | F28: 7 | J28: =SUM(C28:I28) -> 13 | K28: =C28*6200 -> 37200 | N28: =F28*5580 -> 39060 | O28: =G28*4340 -> 0 | R28: =SUM(K28:Q28) -> 76260 | S28: =(C28+D28+E28+F28+I28+G28+H28)*3923 -> 50999
A29: 핑키니하이브리드하드 | B29: P00000UH | C29: 44 | E29: 153 | F29: 917 | J29: =SUM(C29:I29) -> 1114 | K29: =C29*40000 -> 1760000 | L29: =D29*30800 -> 0 | M29: =E29*30800 -> 4712400 | N29: =F29*34000 -> 31178000 | P29: =H29*34000 -> 0 | R29: =SUM(K29:Q29) -> 37650400 | S29: =(C29+D29+E29+F29+I29+G29+H29)*17852 -> 19887128
A30: 루비하드 | B30: P00000TI | C30: 58 | E30: 312 | F30: 773 | J30: =SUM(C30:I30) -> 1143 | K30: =C30*37800 -> 2192400 | L30: =D30*27800 -> 0 | M30: =E30*27800 -> 8673600 | N30: =F30*32130 -> 24836490 | P30: =H30*32130 -> 0 | R30: =SUM(K30:Q30) -> 35702490 | S30: =(C30+D30+E30+F30+I30+G30+H30)*15958 -> 18239994
A31: 라이코젯데저트하드 | B31: P00000BY | C31: 31 | E31: 104 | F31: 670 | J31: =SUM(C31:I31) -> 805 | K31: =C31*37800 -> 1171800 | L31: =D31*27800 -> 0 | M31: =E31*27800 -> 2891200 | N31: =F31*32130 -> 21527100 | P31: =H31*32130 -> 0 | R31: =SUM(K31:Q31) -> 25590100 | S31: =(C31+D31+E31+F31+I31+G31+H31)*15958 -> 12846190
A32: 라이코젯라벤더하드 | B32: P00000BZ | C32: 15 | E32: 93 | F32: 216 | J32: =SUM(C32:I32) -> 324 | K32: =C32*37800 -> 567000 | L32: =D32*27800 -> 0 | M32: =E32*27800 -> 2585400 | N32: =F32*32130 -> 6940080 | P32: =H32*32130 -> 0 | R32: =SUM(K32:Q32) -> 10092480 | S32: =(C32+D32+E32+F32+I32+G32+H32)*15958 -> 5170392
A33: 로즈퓨어하드 | B33: P00000CH | C33: 11 | E33: 100 | F33: 268 | G33: 1 | J33: =SUM(C33:I33) -> 380 | K33: =C33*37800 -> 415800 | L33: =D33*27800 -> 0 | M33: =E33*27800 -> 2780000 | N33: =F33*32130 -> 8610840 | O33: =G33*30240 -> 30240 | P33: =H33*32130 -> 0 | R33: =SUM(K33:Q33) -> 11836880 | S33: =(C33+D33+E33+F33+I33+G33+H33)*16680 -> 6338400
A34: 맨니피코하드 | B34: P00000CG | C34: 27 | E34: 104 | F34: 419 | J34: =SUM(C34:I34) -> 550 | K34: =C34*37800 -> 1020600 | L34: =D34*27800 -> 0 | M34: =E34*27800 -> 2891200 | N34: =F34*32130 -> 13462470 | P34: =H34*32130 -> 0 | R34: =SUM(K34:Q34) -> 17374270 | S34: =(C34+D34+E34+F34+I34+G34+H34)*16680 -> 9174000
A35: 올리브하드 | B35: P00000CA | J35: =SUM(C35:I35) -> 0 | K35: =C35*37800 -> 0 | L35: =D35*27800 -> 0 | M35: =E35*27800 -> 0 | N35: =F35*32130 -> 0 | P35: =H35*32130 -> 0 | R35: =SUM(K35:Q35) -> 0 | S35: =(C35+D35+E35+F35+I35+G35+H35)*16680 -> 0
A36: 라이코플렉스바닐라하드 | B36: P00000BW | C36: 7 | E36: 9 | F36: 43 | J36: =SUM(C36:I36) -> 59 | K36: =C36*37800 -> 264600 | L36: =D36*27800 -> 0 | M36: =E36*27800 -> 250200 | N36: =F36*32130 -> 1381590 | P36: =H36*32130 -> 0 | R36: =SUM(K36:Q36) -> 1896390 | S36: =(C36+D36+E36+F36+I36+G36+H36)*16680 -> 984120
A37: 소베리딜리셔스하드 | B37: P00000CI | C37: 6 | E37: 50 | F37: 135 | J37: =SUM(C37:I37) -> 191 | K37: =C37*37800 -> 226800 | L37: =D37*27800 -> 0 | M37: =E37*27800 -> 1390000 | N37: =F37*32130 -> 4337550 | P37: =H37*32130 -> 0 | R37: =SUM(K37:Q37) -> 5954350 | S37: =(C37+D37+E37+F37+I37+G37+H37)*16680 -> 3185880
A38: 아쥴렌하드 | B38: P00000CE | C38: 5 | E38: 11 | F38: 46 | J38: =SUM(C38:I38) -> 62 | K38: =C38*37800 -> 189000 | L38: =D38*27800 -> 0 | M38: =E38*27800 -> 305800 | N38: =F38*32130 -> 1477980 | P38: =H38*32130 -> 0 | R38: =SUM(K38:Q38) -> 1972780 | S38: =(C38+D38+E38+F38+I38+G38+H38)*16680 -> 1034160
A39: 액티브골드 | B39: P00000KH | J39: =SUM(C39:I39) -> 0 | K39: =C39*37800 -> 0 | L39: =D39*27800 -> 0 | M39: =E39*27800 -> 0 | N39: =F39*32130 -> 0 | P39: =H39*32130 -> 0 | R39: =SUM(K39:Q39) -> 0 | S39: =(C39+D39+E39+F39+I39+G39+H39)*15688 -> 0
A40: 알로에베라하드 | B40: P00000CD | C40: 11 | E40: 18 | F40: 217 | J40: =SUM(C40:I40) -> 246 | K40: =C40*37800 -> 415800 | L40: =D40*27800 -> 0 | M40: =E40*27800 -> 500400 | N40: =F40*32130 -> 6972210 | P40: =H40*32130 -> 0 | R40: =SUM(K40:Q40) -> 7888410 | S40: =(C40+D40+E40+F40+I40+G40+H40)*15688 -> 3859248
...

Sheet 상품코드_4월-NEW1
E4: 인증/마스터
D6: 도매 | E6: P00000QE | J6: P00000QD | W6: P0000BLR | AD6: P0000BLA | AK6: P00000ZC | AO6: P00000YZ | AS6: P00000VM | BE6: P00000YS | BF6: P00000YU
E7: 하드왁스500g 24개 | J7: 하드왁스15개 | W7: 비즈 왁스 4종 | AD7: 비즈 왁스 4종 | AK7: 라이콘 컵 왁스 비즈 110g 5개 이상 10% (로제트 / 라벤더 / 하이브리드 / 핑키니) | AO7: 라이콘 컵 왁스 비즈 110g 세트 (로제트 / 라벤더 / 하이브리드 / 핑키니) | AS7: [묶음할인 15%] 하드왁스 1Kg 5개이상 | BE7: 제모미인 페이스왁싱 스타터 키트 20%할인 | BF7: 라이콘 바디왁싱 스타터 키트20%할인
A8: 하드왁스 | E8: G | F8: H | G8: I | H8: J | I8: K | J8: CI | K8: CJ | L8: CK | M8: CL | N8: CM | O8: CN | P8: CO | Q8: CP | R8: CQ | S8: CR | T8: CS | U8: CT | V8: CU | W8: Q | X8: R | Y8: S | Z8: T | AA8: U | AB8: V | AC8: W | AD8: J | AE8: K | AF8: L | AG8: M | AH8: N | AI8: O | AJ8: P | AK8: A | AL8: B | AM8: C | AN8: D | AO8: D | AP8: E | AQ8: H | AR8: I | AS8: CW | AT8: CX | AU8: CY | AV8: CZ | AW8: DA | AX8: DB | AY8: DC | AZ8: DD | BA8: DE | BB8: DF | BC8: DG | BD8: DH | BE8: - | BF8: -
A9: P00000HT | B9: - | C9: 라이코젯아이브로우500 | D9: 75 | BE9: 2 | BG9: =SUM(D9:BF9) -> 77
A10: P00000BV | B10: - | C10: 라이코드림하이브리드500 | D10: 5 | BG10: =SUM(D10:BF10) -> 5
A11: P00000CB | B11: - | C11: 라이코넥화이트500 | D11: 5 | BG11: =SUM(D11:BF11) -> 5
A12: P00000BX | B12: - | C12: 라이코텍슈퍼베리500 | H12: 24 | BG12: =SUM(D12:BF12) -> 24
A13: P00000XE | B13: - | C13: 맨니피코하이브리드500 | D13: 6 | BG13: =SUM(D13:BF13) -> 6
A14: P0000BIF | B14: CI | C14: 라이코젯라벤다비즈800 | D14: 1 | BG14: =SUM(D14:BF14) -> 1
B15: CJ | C15: 로제트비즈800 | D15: 3 | BG15: =SUM(D15:BF15) -> 3
B16: CK | C16: 핑키니하이브리드비즈800 | D16: 8 | BG16: =SUM(D16:BF16) -> 8
B17: CL | C17: 라이코젯라벤다비즈5kg | D17: 1 | Z17: 2 | BG17: =SUM(D17:BF17) -> 3
B18: CM | C18: 로제트비즈5kg | D18: 2 | BG18: =SUM(D18:BF18) -> 2
B19: CN | C19: 라이코드림하이브리드비즈5kg | D19: 2 | Y19: 1 | BG19: =SUM(D19:BF19) -> 3
B20: CO | C20: 핑키니하이브리드비즈5kg | D20: 9 | AC20: 3 | BG20: =SUM(D20:BF20) -> 12
A21: P0000BLD | B21: F | C21: 라이코드림하이브리드비즈800 | BG21: =SUM(D21:BF21) -> 0
B22: G | C22: 라이코젯 라벤더 비즈 왁스 800g | BG22: =SUM(D22:BF22) -> 0
B23: H | C23: 로제트 비즈 왁스 800g | BG23: =SUM(D23:BF23) -> 0
B24: I | C24: 핑키니 하이브리드 비즈 왁스 800g | BG24: =SUM(D24:BF24) -> 0
A25: P0000BMJ | B25: - | C25: 선샤인 비즈왁스 800g (1박스 18개) | D25: 4 | BG25: =SUM(D25:BF25) -> 4
A26: P0000BMI | B26: - | C26: 선샤인비즈왁스800 | D26: 30 | BG26: =SUM(D26:BF26) -> 30
A27: 500g총합계 | D27: =SUM(D9:D26) -> 151 | E27: =SUM(E9:E26) -> 0 | F27: =SUM(F9:F26) -> 0 | G27: =SUM(G9:G26) -> 0 | H27: =SUM(H9:H26) -> 24 | I27: =SUM(I9:I26) -> 0 | J27: =SUM(J9:J26) -> 0 | K27: =SUM(K9:K26) -> 0 | ... BG27: =SUM(BG9:BG26) -> 183
A28: P00000ZB | B28: A | C28: 라이콘컵왁스비즈(로제트) | D28: 2 | AO28: 1 | BG28: =SUM(D28:BF28) -> 3
B29: B | C29: 라이콘컵왁스비즈(라벤다) | D29: 6 | AP29: 1 | BG29: =SUM(D29:BF29) -> 7
B30: C | C30: 라이콘컵왁스비즈(하이브리드) | D30: 1 | AM30: 5 | BG30: =SUM(D30:BF30) -> 6
B31: D | C31: 라이콘컵왁스비즈(핑키니) | D31: 6 | AN31: 7 | BG31: =SUM(D31:BF31) -> 13
A32: P00000UH | B32: - | C32: 핑키니하이브리드하드 | D32: 44 | V32: 153 | BD32: 917 | BG32: =SUM(D32:BF32) -> 1114
A33: P00000TI | B33: - | C33: 루비하드 | D33: 58 | U33: 312 | AS33: 773 | BG33: =SUM(D33:BF33) -> 1143
A34: P00000BY | B34: - | C34: 라이코젯데저트하드 | D34: 31 | S34: 104 | AU34: 670 | BG34: =SUM(D34:BF34) -> 805
A35: P00000BZ | B35: - | C35: 라이코젯라벤더하드 | D35: 15 | T35: 93 | AY35: 216 | BG35: =SUM(D35:BF35) -> 324
A36: P00000CH | B36: - | C36: 로즈퓨어하드 | D36: 11 | Q36: 100 | AV36: 1 | AX36: 268 | BG36: =SUM(D36:BF36) -> 380
A37: P00000CG | B37: - | C37: 맨니피코하드 | D37: 27 | M37: 104 | AW37: 419 | BG37: =SUM(D37:BF37) -> 550
A38: P00000CA | B38: - | C38: 올리브하드 | BG38: =SUM(D38:BF38) -> 0
A39: P00000BW | B39: - | C39: 라이코플렉스바닐라하드 | D39: 7 | O39: 9 | BD39: 43 | BG39: =SUM(D39:BF39) -> 59
A40: P00000CI | B40: - | C40: 소베리딜리셔스하드 | D40: 6 | R40: 50 | BA40: 135 | BG40: =SUM(D40:BF40) -> 191
A41: P00000CE | B41: - | C41: 아쥴렌하드 | D41: 5 | K41: 11 | AZ41: 46 | BG41: =SUM(D41:BF41) -> 62
A42: P00000KH | B42: - | C42: 액티브골드 | BG42: =SUM(D42:BF42) -> 0
A43: P00000CD | B43: - | C43: 알로에베라하드 | D43: 11 | P43: 18 | AT43: 217 | BG43: =SUM(D43:BF43) -> 246
A44: P00000CF | B44: - | C44: 아프리콧하드 | D44: 1 | BG44: =SUM(D44:BF44) -> 1
...
